<?xml version="1.0" ?>
<robot name="minirapid1">
  <link name="base_link">
    <inertial>
      <origin
        xyz="0.00640831749202908 0.00226187286973015 0.0859341982829709"
        rpy="0 0 0" />
      <mass
        value="4.39662154313249" />
      <inertia
        ixx="0.0791697561558385"
        ixy="-0.00256646668517333"
        ixz="-0.0014696968337059"
        iyy="0.186325439910284"
        iyz="-0.000788647453344782"
        izz="0.23533402482209" />
    </inertial>
    <visual>
      <origin
        xyz="0 0 0"
        rpy="0 0 0" />
      <geometry>
        <mesh
          filename="package://minirapid1/meshes/base_link.STL" />
      </geometry>
      <material
        name="">
        <color
          rgba="0.792156862745098 0.819607843137255 0.933333333333333 1" />
      </material>
    </visual>
    <collision>
      <origin
        xyz="0 0 0"
        rpy="0 0 0" />
      <geometry>
        <mesh
          filename="package://minirapid1/meshes/base_link.STL" />
      </geometry>
    </collision>
  </link>

  <link name="left_wheel_link">
    <inertial>
      <origin
        xyz="-1.11022302462516E-15 -0.0305000000000009 -0.000522969789136768"
        rpy="0 0 0" />
      <mass
        value="0.149150016733407" />
      <inertia
        ixx="0.000103004096524672"
        ixy="4.38599642468359E-19"
        ixz="2.59227726020217E-19"
        iyy="0.000183918976866177"
        iyz="-3.56451784210186E-19"
        izz="0.000103004096524671" />
    </inertial>
    <visual>
      <origin
        xyz="0 0 0"
        rpy="0 0 0" />
      <geometry>
        <mesh
          filename="package://minirapid1/meshes/left_wheel_link.STL" />
      </geometry>
      <material
        name="">
        <color
          rgba="0.792156862745098 0.819607843137255 0.933333333333333 1" />
      </material>
    </visual>
    <collision>
      <origin
        xyz="0 0 0"
        rpy="0 0 0" />
      <geometry>
        <mesh
          filename="package://minirapid1/meshes/left_wheel_link.STL" />
      </geometry>
    </collision>
  </link>

  <joint name="left_wheel_joint" type="continuous">
    <origin
      xyz="0 0.153 0.019926"
      rpy="0 0 0" />
    <parent
      link="base_link" />
    <child
      link="left_wheel_link" />
    <axis
      xyz="0 1 0" />
  </joint>

  <link name="right_wheel_link">
    <inertial>
      <origin
        xyz="-7.7715611723761E-16 0.0305000000000009 -0.000522969789136771"
        rpy="0 0 0" />
      <mass
        value="0.149150016733407" />
      <inertia
        ixx="0.000103004096524672"
        ixy="-1.28084450377781E-19"
        ixz="-2.60951883342545E-19"
        iyy="0.000183918976866177"
        iyz="3.46896913361451E-19"
        izz="0.000103004096524671" />
    </inertial>
    <visual>
      <origin
        xyz="0 0 0"
        rpy="0 0 0" />
      <geometry>
        <mesh
          filename="package://minirapid1/meshes/right_wheel_link.STL" />
      </geometry>
      <material
        name="">
        <color
          rgba="0.792156862745098 0.819607843137255 0.933333333333333 1" />
      </material>
    </visual>
    <collision>
      <origin
        xyz="0 0 0"
        rpy="0 0 0" />
      <geometry>
        <mesh
          filename="package://minirapid1/meshes/right_wheel_link.STL" />
      </geometry>
    </collision>
  </link>

  <joint name="right_wheel_joint" type="continuous">
    <origin
      xyz="0 -0.153 0.019926"
      rpy="0 0 0" />
    <parent
      link="base_link" />
    <child
      link="right_wheel_link" />
    <axis
      xyz="0 1 0" />
  </joint>

  <link name="laser">
    <inertial>
      <origin
        xyz="-0.00105134047928768 -0.000900283053485745 -0.0102612743782634"
        rpy="0 0 0" />
      <mass
        value="0.0764074110658063" />
      <inertia
        ixx="2.6442911831536E-05"
        ixy="1.09596059550054E-06"
        ixz="1.77367768412782E-08"
        iyy="2.59904733259173E-05"
        iyz="1.44000295483743E-08"
        izz="4.72874256940087E-05" />
    </inertial>
    <visual>
      <origin
        xyz="0 0 0"
        rpy="0 0 0" />
      <geometry>
        <mesh
          filename="package://minirapid1/meshes/rplidar_link.STL" />
      </geometry>
      <material
        name="">
        <color
          rgba="0.309803921568627 0.309803921568627 0.309803921568627 1" />
      </material>
    </visual>
    <collision>
      <origin
        xyz="0 0 0"
        rpy="0 0 0" />
      <geometry>
        <mesh
          filename="package://minirapid1/meshes/rplidar_link.STL" />
      </geometry>
    </collision>
  </link>

  <joint name="rplidar_joint" type="continuous">
    <origin
      xyz="0.24997 0.11002 0.19565"
      rpy="0 0 0" />
    <parent
      link="base_link" />
    <child
      link="laser" />
    <axis
      xyz="0 0 1" />
  </joint>

  <joint name="imu_joint" type="fixed">
    <parent link="base_link"/>
    <child link="imu_link"/>
    <origin xyz="0.0 0 0.088" rpy="0 0 0"/>
  </joint>
  <link name="imu_link"/> 

  <!-- Camera Center -->
  <joint name="zed_camera_center_joint" type="fixed">
      <parent link="base_link"/>
      <child link="zed_camera_center"/>
      <origin xyz="0.0 0.0 0.05" rpy="0.0 1.57 0.0" />
  </joint>

  <link name="zed_camera_center">
      <visual>
          <origin xyz="0 0 0" rpy="0 0 0"/>
          <geometry>
              <mesh filename="package://zed_wrapper/urdf/models/zed.stl" />
          </geometry>
          <material name="" />
      </visual>
  </link>

  <!-- Left Camera -->
  <joint name="zed_left_camera_joint" type="fixed">
      <parent link="zed_camera_center"/>
      <child link="zed_left_camera_frame"/>
      <origin xyz="0 0.06 0" rpy="0 0 0" />
  </joint>

  <link name="zed_left_camera_frame" />

  <joint name="zed_left_camera_optical_joint" type="fixed">
      <origin xyz="0 0 0" rpy="-1.57 0.0 -1.57"/>
      <parent link="zed_left_camera_frame"/>
      <child link="zed_left_camera_optical_frame"/>
  </joint>

  <link name="zed_left_camera_optical_frame"/>

  <!-- Right Camera -->
  <joint name="zed_right_camera_joint" type="fixed">
      <parent link="zed_camera_center"/>
      <child link="zed_right_camera_frame"/>
      <origin xyz="0 -0.06 0" rpy="0 0 0" />
  </joint>

  <link name="zed_right_camera_frame" />

  <joint name="zed_right_camera_optical_joint" type="fixed">
      <origin xyz="0 0 0" rpy="-1.57 0.0 -1.57"/>
      <parent link="zed_right_camera_frame"/>
      <child link="zed_right_camera_optical_frame"/>
  </joint>

  <link name="zed_right_camera_optical_frame"/>

</robot>
